Workbook

Sheet Paper LBO - Template
C2: Dynacast LBO - Summer 2025
C3: ($ in millions) | D3: Assumptions
C5: Entry Assumptions
C6: EV Multiple | D6: 8.9
C7: EBITDA | D7: =D30 -> 123.5
C8: Enterprise Value | D8: =D6*D7 -> 1099.15
C9: Existing Debt | D9: 486
C10: Implied Value of Equity | D10: =D8-D9 -> 613.15
C11: Holding Period | D11: 5
C12: Max Leverage | D12: 4.25
C13: Mgmt. Rollover | D13: 0.05
C14: Est. Txn Fees & Exp (% of TEV) | D14: 0.03
C16: Sources and Uses
C18: Sources | F18: Uses | K18: 45555
C19: Revolver | D19: 0 | F19: Consideration to Equity Holders | I19: =D10 -> 613.15 | K19: 3M SOFR | L19: Spread
C20: Term Loan B | D20: =$D$12*$D$7 -> 524.875 | F20: Refi Existing Debt | I20: =D9 -> 486 | K20: 0.0533 | L20: 0.0425
C21: Mgmt. Rollover | D21: =$D$10*$D$13 -> 30.6575 | F21: Est. Txn Fees & Expenses | I21: =$D$8*$D$14 -> 32.9745 | K21: 0.0533 | L21: 0.0475
C22: Sponsor Equity Check | D22: =D23-SUM(D19:D21) -> 576.592
C23: Total Sources | D23: =I23 -> 1132.1245 | F23: Total Uses | I23: =I19+I20+I21 -> 1132.1245
D26: PF LTM Sep | E26: Projected
C27: Simple P&L | D27: 2014 | E27: =D27+1 -> 2015 | F27: =+E27+1 -> 2016 | G27: =+F27+1 -> 2017 | H27: =+G27+1 -> 2018 | I27: =+H27+1 -> 2019
C28: Revenue | D28: 650 | E28: =D28*(1+E29) -> 708.5 | F28: =E28*(1+F29) -> 772.265 | G28: =F28*(1+G29) -> 841.76885 | H28: =G28*(1+H29) -> 917.52805 | I28: =H28*(1+I29) -> 1000.1056
C29: % Growth | D29: 0.081 | E29: 0.09 | F29: 0.09 | G29: 0.09 | H29: 0.09 | I29: 0.09
C30: EBITDA | D30: 123.5 | E30: =E28*E31 -> 141.7 | F30: =F28*F31 -> 162.17565 | G30: =G28*G31 -> 176.77146 | H30: =H28*H31 -> 192.68089 | I30: =I28*I31 -> 210.02217
C31: % Margin | D31: =D30/D28 -> 0.19 | E31: 0.2 | F31: 0.21 | G31: 0.21 | H31: 0.21 | I31: 0.21
C32: D&A | D32: 30 | E32: =E44 -> 32.7 | F32: =F44 -> 35.643 | G32: =G44 -> 38.85087 | H32: =H44 -> 42.347448 | I32: =I44 -> 46.158719
C33: % Of Capex | D33: =D32/$D$44 -> 1 | E33: =E32/E44 -> 1 | F33: =F32/F44 -> 1 | G33: =G32/G44 -> 1 | H33: =H32/H44 -> 1 | I33: =I32/I44 -> 1
C34: EBIT | D34: 74.8 | E34: =E30-E32 -> 109 | F34: =F30-F32 -> 126.53265 | G34: =G30-G32 -> 137.92059 | H34: =H30-H32 -> 150.33344 | I34: =I30-I32 -> 163.86345
C35: % Margin | D35: =D34/D28 -> 0.11507692 | E35: =E34/E28 -> 0.15384615 | F35: =F34/F28 -> 0.16384615 | G35: =G34/G28 -> 0.16384615 | H35: =H34/H28 -> 0.16384615 | I35: =I34/I28 -> 0.16384615
C36: Net Interest Expense | D36: -- | E36: =E63 -> 50.939749 | F36: =F63 -> 46.182315 | G36: =G63 -> 39.959327 | H36: =H63 -> 32.36076 | I36: =I63 -> 23.19874
C37: EBT | D37: 23.4 | E37: =E34-E36 -> 58.060251 | F37: =F34-F36 -> 80.350335 | G37: =G34-G36 -> 97.961262 | H37: =H34-H36 -> 117.97268 | I37: =I34-I36 -> 140.66471
C38: Income Tax Expense | D38: -- | E38: =E37*E54 -> 14.515063 | F38: =F37*F54 -> 20.087584 | G38: =G37*G54 -> 24.490315 | H38: =H37*H54 -> 29.49317 | I38: =I37*I54 -> 35.166178
C39: Net Income | D39: 10.5 | E39: =E37-E38 -> 43.545188 | F39: =F37-F38 -> 60.262751 | G39: =G37-G38 -> 73.470946 | H39: =H37-H38 -> 88.479511 | I39: =I37-I38 -> 105.49853
C40: % Margin | D40: =D39/D28 -> 0.016153846 | E40: =E39/E28 -> 0.061461098 | F40: =F39/F28 -> 0.078033772 | G40: =G39/G28 -> 0.087281617 | H40: =H39/H28 -> 0.096432486 | I40: =I39/I28 -> 0.1054874
D41: PF LTM | E41: Projected
C42: Simple FCF Build | D42: 2014 | E42: =D42+1 -> 2015 | F42: =+E42+1 -> 2016 | G42: =+F42+1 -> 2017 | H42: =+G42+1 -> 2018 | I42: =+H42+1 -> 2019
C43: EBITDA | D43: =D30 -> 123.5 | E43: =E30 -> 141.7 | F43: =F30 -> 162.17565 | G43: =G30 -> 176.77146 | H43: =H30 -> 192.68089 | I43: =I30 -> 210.02217
C44: Capex | D44: 30 | E44: =E28*$E$50 -> 32.7 | F44: =F28*$E$50 -> 35.643 | G44: =G28*$E$50 -> 38.85087 | H44: =H28*$E$50 -> 42.347448 | I44: =I28*$E$50 -> 46.158719
C45: Net Change in WC | D45: -- | E45: =E53-D53 -> 4.5045 | F45: =F53-E53 -> 4.909905 | G45: =G53-F53 -> 5.3517965 | H45: =H53-G53 -> 5.8334581 | I45: =I53-H53 -> 6.3584694
C46: Interest | D46: -- | E46: =E36 -> 50.939749 | F46: =F36 -> 46.182315 | G46: =G36 -> 39.959327 | H46: =H36 -> 32.36076 | I46: =I36 -> 23.19874
...

Sheet Bull Case
C2: Dynacast LBO - Bull Case ($ in millions)
C3: ($ in millions) | D3: Assumptions
C4: BULL CASE - scenario tab. Changed inputs shaded yellow (blue font). Sources and rationale in rows 99+.
C5: Entry Assumptions
C6: EV Multiple | D6: 8.9
C7: EBITDA | D7: =D30 -> 123.5
C8: Enterprise Value | D8: =D6*D7 -> 1099.15
C9: Existing Debt | D9: 486
C10: Implied Value of Equity | D10: =D8-D9 -> 613.15
C11: Holding Period | D11: 5
C12: Max Leverage | D12: 4.25
C13: Mgmt. Rollover | D13: 0.05
C14: Est. Txn Fees & Exp (% of TEV) | D14: 0.03
C16: Sources and Uses
C18: Sources | F18: Uses | K18: 45555
C19: Revolver | D19: 0 | F19: Consideration to Equity Holders | I19: =D10 -> 613.15 | K19: 3M SOFR | L19: Spread
C20: Term Loan B | D20: =$D$12*$D$7 -> 524.875 | F20: Refi Existing Debt | I20: =D9 -> 486 | K20: 0.0533 | L20: 0.0425
C21: Mgmt. Rollover | D21: =$D$10*$D$13 -> 30.6575 | F21: Est. Txn Fees & Expenses | I21: =$D$8*$D$14 -> 32.9745 | K21: 0.0533 | L21: 0.0475
C22: Sponsor Equity Check | D22: =D23-SUM(D19:D21) -> 576.592
C23: Total Sources | D23: =I23 -> 1132.1245 | F23: Total Uses | I23: =I19+I20+I21 -> 1132.1245
D26: PF LTM Sep | E26: Projected
C27: Simple P&L | D27: 2014 | E27: =D27+1 -> 2015 | F27: =+E27+1 -> 2016 | G27: =+F27+1 -> 2017 | H27: =+G27+1 -> 2018 | I27: =+H27+1 -> 2019
C28: Revenue | D28: 650 | E28: =D28*(1+E29) -> 727.35 | F28: =E28*(1+F29) -> 813.90465 | G28: =F28*(1+G29) -> 910.7593 | H28: =G28*(1+H29) -> 1019.1397 | I28: =H28*(1+I29) -> 1140.4173
C29: % Growth | D29: 0.081 | E29: 0.119 | F29: 0.119 | G29: 0.119 | H29: 0.119 | I29: 0.119
C30: EBITDA | D30: 123.5 | E30: =E28*E31 -> 149.10675 | F30: =F28*F31 -> 174.9895 | G30: =G28*G31 -> 195.81325 | H30: =H28*H31 -> 219.11503 | I30: =I28*I31 -> 245.18972
C31: % Margin | D31: =D30/D28 -> 0.19 | E31: 0.205 | F31: 0.215 | G31: 0.215 | H31: 0.215 | I31: 0.215
C32: D&A | D32: 30 | E32: =E44 -> 33.57 | F32: =F44 -> 37.56483 | G32: =G44 -> 42.035045 | H32: =H44 -> 47.037215 | I32: =I44 -> 52.634644
C33: % Of Capex | D33: =D32/$D$44 -> 1 | E33: =E32/E44 -> 1 | F33: =F32/F44 -> 1 | G33: =G32/G44 -> 1 | H33: =H32/H44 -> 1 | I33: =I32/I44 -> 1
C34: EBIT | D34: 74.8 | E34: =E30-E32 -> 115.53675 | F34: =F30-F32 -> 137.42467 | G34: =G30-G32 -> 153.77821 | H34: =H30-H32 -> 172.07781 | I34: =I30-I32 -> 192.55507
C35: % Margin | D35: =D34/D28 -> 0.11507692 | E35: =E34/E28 -> 0.15884615 | F35: =F34/F28 -> 0.16884615 | G35: =G34/G28 -> 0.16884615 | H35: =H34/H28 -> 0.16884615 | I35: =I34/I28 -> 0.16884615
C36: Net Interest Expense | D36: -- | E36: =E63 -> 50.75898 | F36: =F63 -> 45.470598 | G36: =G63 -> 38.34306 | H36: =H63 -> 29.382194 | I36: =I63 -> 18.29243
C37: EBT | D37: 23.4 | E37: =E34-E36 -> 64.77777 | F37: =F34-F36 -> 91.954075 | G37: =G34-G36 -> 115.43516 | H37: =H34-H36 -> 142.69565 | I37: =I34-I36 -> 174.26272
C38: Income Tax Expense | D38: -- | E38: =E37*E54 -> 16.194443 | F38: =F37*F54 -> 22.988519 | G38: =G37*G54 -> 28.858789 | H38: =H37*H54 -> 35.673912 | I38: =I37*I54 -> 43.565679
C39: Net Income | D39: 10.5 | E39: =E37-E38 -> 48.583328 | F39: =F37-F38 -> 68.965556 | G39: =G37-G38 -> 86.576367 | H39: =H37-H38 -> 107.02174 | I39: =I37-I38 -> 130.69704
C40: % Margin | D40: =D39/D28 -> 0.016153846 | E40: =E39/E28 -> 0.066794979 | F40: =F39/F28 -> 0.084734196 | G40: =G39/G28 -> 0.095059547 | H40: =H39/H28 -> 0.10501185 | I40: =I39/I28 -> 0.11460457
D41: PF LTM | E41: Projected
C42: Simple FCF Build | D42: 2014 | E42: =D42+1 -> 2015 | F42: =+E42+1 -> 2016 | G42: =+F42+1 -> 2017 | H42: =+G42+1 -> 2018 | I42: =+H42+1 -> 2019
C43: EBITDA | D43: =D30 -> 123.5 | E43: =E30 -> 149.10675 | F43: =F30 -> 174.9895 | G43: =G30 -> 195.81325 | H43: =H30 -> 219.11503 | I43: =I30 -> 245.18972
C44: Capex | D44: 30 | E44: =E28*$E$50 -> 33.57 | F44: =F28*$E$50 -> 37.56483 | G44: =G28*$E$50 -> 42.035045 | H44: =H28*$E$50 -> 47.037215 | I44: =I28*$E$50 -> 52.634644
C45: Net Change in WC | D45: -- | E45: =E53-D53 -> 5.95595 | F45: =F53-E53 -> 6.6647081 | G45: =G53-F53 -> 7.4578083 | H45: =H53-G53 -> 8.3452875 | I45: =I53-H53 -> 9.3383767
...

Sheet Bear Case
C2: Dynacast LBO - Bear Case ($ in millions)
C3: ($ in millions) | D3: Assumptions
C4: BEAR CASE - scenario tab. Changed inputs shaded yellow (blue font). Sources and rationale in rows 99+.
C5: Entry Assumptions
C6: EV Multiple | D6: 8.9
C7: EBITDA | D7: =D30 -> 123.5
C8: Enterprise Value | D8: =D6*D7 -> 1099.15
C9: Existing Debt | D9: 486
C10: Implied Value of Equity | D10: =D8-D9 -> 613.15
C11: Holding Period | D11: 5
C12: Max Leverage | D12: 4.25
C13: Mgmt. Rollover | D13: 0.05
C14: Est. Txn Fees & Exp (% of TEV) | D14: 0.03
C16: Sources and Uses
C18: Sources | F18: Uses | K18: 45555
C19: Revolver | D19: 0 | F19: Consideration to Equity Holders | I19: =D10 -> 613.15 | K19: 3M SOFR | L19: Spread
C20: Term Loan B | D20: =$D$12*$D$7 -> 524.875 | F20: Refi Existing Debt | I20: =D9 -> 486 | K20: 0.0533 | L20: 0.0425
C21: Mgmt. Rollover | D21: =$D$10*$D$13 -> 30.6575 | F21: Est. Txn Fees & Expenses | I21: =$D$8*$D$14 -> 32.9745 | K21: 0.0533 | L21: 0.0475
C22: Sponsor Equity Check | D22: =D23-SUM(D19:D21) -> 576.592
C23: Total Sources | D23: =I23 -> 1132.1245 | F23: Total Uses | I23: =I19+I20+I21 -> 1132.1245
D26: PF LTM Sep | E26: Projected
C27: Simple P&L | D27: 2014 | E27: =D27+1 -> 2015 | F27: =+E27+1 -> 2016 | G27: =+F27+1 -> 2017 | H27: =+G27+1 -> 2018 | I27: =+H27+1 -> 2019
C28: Revenue | D28: 650 | E28: =D28*(1+E29) -> 702 | F28: =E28*(1+F29) -> 758.16 | G28: =F28*(1+G29) -> 818.8128 | H28: =G28*(1+H29) -> 884.31782 | I28: =H28*(1+I29) -> 955.06325
C29: % Growth | D29: 0.081 | E29: 0.08 | F29: 0.08 | G29: 0.08 | H29: 0.08 | I29: 0.08
C30: EBITDA | D30: 123.5 | E30: =E28*E31 -> 136.89 | F30: =F28*F31 -> 147.8412 | G30: =G28*G31 -> 159.6685 | H30: =H28*H31 -> 172.44198 | I30: =I28*I31 -> 186.23733
C31: % Margin | D31: =D30/D28 -> 0.19 | E31: 0.195 | F31: 0.195 | G31: 0.195 | H31: 0.195 | I31: 0.195
C32: D&A | D32: 30 | E32: =E44 -> 32.4 | F32: =F44 -> 34.992 | G32: =G44 -> 37.79136 | H32: =H44 -> 40.814669 | I32: =I44 -> 44.079842
C33: % Of Capex | D33: =D32/$D$44 -> 1 | E33: =E32/E44 -> 1 | F33: =F32/F44 -> 1 | G33: =G32/G44 -> 1 | H33: =H32/H44 -> 1 | I33: =I32/I44 -> 1
C34: EBIT | D34: 74.8 | E34: =E30-E32 -> 104.49 | F34: =F30-F32 -> 112.8492 | G34: =G30-G32 -> 121.87714 | H34: =H30-H32 -> 131.62731 | I34: =I30-I32 -> 142.15749
C35: % Margin | D35: =D34/D28 -> 0.11507692 | E35: =E34/E28 -> 0.14884615 | F35: =F34/F28 -> 0.14884615 | G35: =G34/G28 -> 0.14884615 | H35: =H34/H28 -> 0.14884615 | I35: =I34/I28 -> 0.14884615
C36: Net Interest Expense | D36: -- | E36: =E63 -> 51.090708 | F36: =F63 -> 47.002975 | G36: =G63 -> 41.945915 | H36: =H63 -> 35.791514 | I36: =I63 -> 28.397555
C37: EBT | D37: 23.4 | E37: =E34-E36 -> 53.399291 | F37: =F34-F36 -> 65.846222 | G37: =G34-G36 -> 79.93121 | H37: =H34-H36 -> 95.835758 | I37: =I34-I36 -> 113.75985
C38: Income Tax Expense | D38: -- | E38: =E37*E54 -> 13.349823 | F38: =F37*F54 -> 16.461556 | G38: =G37*G54 -> 19.982802 | H38: =H37*H54 -> 23.95894 | I38: =I37*I54 -> 28.439963
C39: Net Income | D39: 10.5 | E39: =E37-E38 -> 40.049468 | F39: =F37-F38 -> 49.384667 | G39: =G37-G38 -> 59.948407 | H39: =H37-H38 -> 71.876819 | I39: =I37-I38 -> 85.319889
C40: % Margin | D40: =D39/D28 -> 0.016153846 | E40: =E39/E28 -> 0.057050525 | F40: =F39/F28 -> 0.065137526 | G40: =G39/G28 -> 0.073213813 | H40: =H39/H28 -> 0.081279396 | I40: =I39/I28 -> 0.089334281
D41: PF LTM | E41: Projected
C42: Simple FCF Build | D42: 2014 | E42: =D42+1 -> 2015 | F42: =+E42+1 -> 2016 | G42: =+F42+1 -> 2017 | H42: =+G42+1 -> 2018 | I42: =+H42+1 -> 2019
C43: EBITDA | D43: =D30 -> 123.5 | E43: =E30 -> 136.89 | F43: =F30 -> 147.8412 | G43: =G30 -> 159.6685 | H43: =H30 -> 172.44198 | I43: =I30 -> 186.23733
C44: Capex | D44: 30 | E44: =E28*$E$50 -> 32.4 | F44: =F28*$E$50 -> 34.992 | G44: =G28*$E$50 -> 37.79136 | H44: =H28*$E$50 -> 40.814669 | I44: =I28*$E$50 -> 44.079842
C45: Net Change in WC | D45: -- | E45: =E53-D53 -> 4.004 | F45: =F53-E53 -> 4.32432 | G45: =G53-F53 -> 4.6702656 | H45: =H53-G53 -> 5.0438868 | I45: =I53-H53 -> 5.4473978
...

Sheet Scenario Summary
B2: Dynacast LBO - Scenario Summary ($ in millions)
B4: Metric | C4: Base | D4: Bull | E4: Bear
B5: Revenue growth (2015-19, each yr) | C5: ='Paper LBO - Template'!E29 -> 0.09 | D5: ='Bull Case'!E29 -> 0.119 | E5: ='Bear Case'!E29 -> 0.08
B6: EBITDA margin 2015 | C6: ='Paper LBO - Template'!E31 -> 0.2 | D6: ='Bull Case'!E31 -> 0.205 | E6: ='Bear Case'!E31 -> 0.195
B7: EBITDA margin 2016-19 | C7: ='Paper LBO - Template'!F31 -> 0.21 | D7: ='Bull Case'!F31 -> 0.215 | E7: ='Bear Case'!F31 -> 0.195
B8: Exit EV / EBITDA | C8: ='Paper LBO - Template'!D67 -> 8.9 | D8: ='Bull Case'!D67 -> 10.1 | E8: ='Bear Case'!D67 -> 7.6275304
B9: 2019 Revenue | C9: ='Paper LBO - Template'!I28 -> 1000.1056 | D9: ='Bull Case'!I28 -> 1140.4173 | E9: ='Bear Case'!I28 -> 955.06325
B10: 2019 EBITDA | C10: ='Paper LBO - Template'!I30 -> 210.02217 | D10: ='Bull Case'!I30 -> 245.18972 | E10: ='Bear Case'!I30 -> 186.23733
B11: Term loan balance, end 2019 | C11: ='Paper LBO - Template'!I59 -> 180.5762 | D11: ='Bull Case'!I59 -> 120.79323 | E11: ='Bear Case'!I59 -> 241.78549
B12: Gross leverage, end 2019 | C12: ='Paper LBO - Template'!I60 -> 0.85979589 | D12: ='Bull Case'!I60 -> 0.49265209 | E12: ='Bear Case'!I60 -> 1.2982654
B13: Exit TEV | C13: ='Paper LBO - Template'!D69 -> 1869.1973 | D13: ='Bull Case'!D69 -> 2476.4161 | E13: ='Bear Case'!D69 -> 1420.5309
B14: Equity to holders at exit | C14: ='Paper LBO - Template'!D72 -> 1632.5452 | D14: ='Bull Case'!D72 -> 2281.3304 | E14: ='Bear Case'!D72 -> 1136.1295
B15: Sponsor proceeds | C15: ='Paper LBO - Template'!D74 -> 1469.2907 | D15: ='Bull Case'!D74 -> 2053.1974 | E15: ='Bear Case'!D74 -> 1022.5166
B16: Sponsor equity at entry | C16: ='Paper LBO - Template'!D75 -> 576.592 | D16: ='Bull Case'!D75 -> 576.592 | E16: ='Bear Case'!D75 -> 576.592
B17: MOIC | C17: ='Paper LBO - Template'!D77 -> 2.5482328 | D17: ='Bull Case'!D77 -> 3.5609189 | E17: ='Bear Case'!D77 -> 1.7733797
B18: IRR | C18: ='Paper LBO - Template'!D78 -> 0.20572377 | D18: ='Bull Case'!D78 -> 0.28917661 | E18: ='Bear Case'!D78 -> 0.12139947
B20: Fund hurdle check
B21: Target / floor (user brief) | D21: 25-30% target | E21: 12-15% floor
B22: Result | D22: =IF(AND(D18>=0.25,D18<=0.3),"In 25-30% target band",IF(D18>0.3,"Above band","Below band")) -> In 25-30% target band | E22: =IF(AND(E18>=0.12,E18<=0.15),"In 12-15% band",IF(E18>0.15,"Above band","Below floor")) -> In 12-15% band
B24: All scenarios share entry (8.9x, 4.25x term loan, 3% fees, 5% rollover), tax 25%, capex 4.6% of revenue, NWC 7.7%, 10% exit dilution. Only the three yellow-shaded input groups differ on each scenario tab. Iterative calculation must be on.

Sheet Returns Attribution
B2: Dynacast LBO - Returns Attribution ($ in millions)
C3: Base | D3: Bull | E3: Bear
B5: ENTRY (close, early 2015)
B6: Entry EV / EBITDA | C6: ='Paper LBO - Template'!D6 -> 8.9 | D6: ='Bull Case'!D6 -> 8.9 | E6: ='Bear Case'!D6 -> 8.9
B7: Entry EBITDA (PF LTM) | C7: ='Paper LBO - Template'!D7 -> 123.5 | D7: ='Bull Case'!D7 -> 123.5 | E7: ='Bear Case'!D7 -> 123.5
B8: Entry TEV | C8: ='Paper LBO - Template'!D8 -> 1099.15 | D8: ='Bull Case'!D8 -> 1099.15 | E8: ='Bear Case'!D8 -> 1099.15
B9: Debt at entry (Term Loan B + revolver) | C9: ='Paper LBO - Template'!D20+'Paper LBO - Template'!D19 -> 524.875 | D9: ='Bull Case'!D20+'Bull Case'!D19 -> 524.875 | E9: ='Bear Case'!D20+'Bear Case'!D19 -> 524.875
B10: Entry transaction fees | C10: ='Paper LBO - Template'!I21 -> 32.9745 | D10: ='Bull Case'!I21 -> 32.9745 | E10: ='Bear Case'!I21 -> 32.9745
B11: Total equity invested (sponsor + mgmt rollover) | C11: ='Paper LBO - Template'!D21+'Paper LBO - Template'!D22 -> 607.2495 | D11: ='Bull Case'!D21+'Bull Case'!D22 -> 607.2495 | E11: ='Bear Case'!D21+'Bear Case'!D22 -> 607.2495
B12: of which sponsor equity | C12: ='Paper LBO - Template'!D22 -> 576.592 | D12: ='Bull Case'!D22 -> 576.592 | E12: ='Bear Case'!D22 -> 576.592
B13: Sponsor ownership at entry | C13: =C12/C11 -> 0.94951416 | D13: =D12/D11 -> 0.94951416 | E13: =E12/E11 -> 0.94951416
B14: EXIT (end 2019)
B15: Exit EV / EBITDA | C15: ='Paper LBO - Template'!D67 -> 8.9 | D15: ='Bull Case'!D67 -> 10.1 | E15: ='Bear Case'!D67 -> 7.6275304
B16: Exit EBITDA (2019) | C16: ='Paper LBO - Template'!D68 -> 210.02217 | D16: ='Bull Case'!D68 -> 245.18972 | E16: ='Bear Case'!D68 -> 186.23733
B17: Exit TEV | C17: ='Paper LBO - Template'!D69 -> 1869.1973 | D17: ='Bull Case'!D69 -> 2476.4161 | E17: ='Bear Case'!D69 -> 1420.5309
B18: Debt at exit (Term Loan B) | C18: ='Paper LBO - Template'!D70 -> 180.5762 | D18: ='Bull Case'!D70 -> 120.79323 | E18: ='Bear Case'!D70 -> 241.78549
B19: Exit transaction fees | C19: ='Paper LBO - Template'!D71 -> 56.075919 | D19: ='Bull Case'!D71 -> 74.292484 | E19: ='Bear Case'!D71 -> 42.615928
B20: Equity value to all holders at exit | C20: ='Paper LBO - Template'!D72 -> 1632.5452 | D20: ='Bull Case'!D72 -> 2281.3304 | E20: ='Bear Case'!D72 -> 1136.1295
B21: Sponsor ownership at exit (after mgmt incentive dilution) | C21: ='Paper LBO - Template'!D73 -> 0.9 | D21: ='Bull Case'!D73 -> 0.9 | E21: ='Bear Case'!D73 -> 0.9
B22: BRIDGE 1: CHANGE IN TOTAL EQUITY VALUE (100% of equity, not the sponsor)
B23: Total equity invested at entry | C23: =C11 -> 607.2495 | D23: =D11 -> 607.2495 | E23: =E11 -> 607.2495
B24: + EBITDA growth [(Exit EBITDA - Entry EBITDA) x Entry multiple] | C24: =(C16-C7)*C6 -> 770.04731 | D24: =(D16-D7)*D6 -> 1083.0385 | E24: =(E16-E7)*E6 -> 558.36227
B25: + Multiple expansion [(Exit multiple - Entry multiple) x Exit EBITDA] | C25: =(C15-C6)*C16 -> 0 | D25: =(D15-D6)*D16 -> 294.22766 | E25: =(E15-E6)*E16 -> -236.98135
B26: + Debt paydown [Entry debt - Exit debt] | C26: =C9-C18 -> 344.2988 | D26: =D9-D18 -> 404.08177 | E26: =E9-E18 -> 283.08951
B27: - Entry fees (funded with equity, not in entry TEV) | C27: =-C10 -> -32.9745 | D27: =-D10 -> -32.9745 | E27: =-E10 -> -32.9745
B28: - Exit fees | C28: =-C19 -> -56.075919 | D28: =-D19 -> -74.292484 | E28: =-E19 -> -42.615928
B29: = Equity value to all holders at exit | C29: =SUM(C23:C28) -> 1632.5452 | D29: =SUM(D23:D28) -> 2281.3304 | E29: =SUM(E23:E28) -> 1136.1295
B30: Check vs model exit equity (should be 0.0) | C30: =C29-C20 -> 0 | D30: =D29-D20 -> 0 | E30: =E29-E20 -> 0
B31: Total equity value created (100%) | C31: =C20-C11 -> 1025.2957 | D31: =D20-D11 -> 1674.0809 | E31: =E20-E11 -> 528.88
B32: Share of total equity value created
B33: EBITDA growth | C33: =C24/C31 -> 0.75104901 | D33: =D24/D31 -> 0.64694511 | E33: =E24/E31 -> 1.0557447
B34: Multiple expansion | C34: =C25/C31 -> 0 | D34: =D25/D31 -> 0.17575474 | E34: =E25/E31 -> -0.44808151
B35: Debt paydown | C35: =C26/C31 -> 0.3358044 | D35: =D26/D31 -> 0.24137529 | E35: =E26/E31 -> 0.53526227
B36: Fees | C36: =(C27+C28)/C31 -> -0.086853402 | D36: =(D27+D28)/D31 -> -0.064075149 | E36: =(E27+E28)/E31 -> -0.14292548
B37: BRIDGE 2: RECONCILE TO SPONSOR (ownership changes from the model)
B38: Sponsor share of EBITDA growth (at entry ownership) | C38: =C24*C13 -> 731.17083 | D38: =D24*D13 -> 1028.3604 | E38: =E24*E13 -> 530.17288
B39: Sponsor share of multiple expansion | C39: =C25*C13 -> 0 | D39: =D25*D13 -> 279.37333 | E39: =E25*E13 -> -225.01715
B40: Sponsor share of debt paydown | C40: =C26*C13 -> 326.91659 | D40: =D26*D13 -> 383.68137 | E40: =E26*E13 -> 268.7975
B41: Sponsor share of fees | C41: =(C27+C28)*C13 -> -84.554634 | D41: =(D27+D28)*D13 -> -101.85152 | E41: =(E27+E28)*E13 -> -71.774181
B42: - Dilution: (entry ownership - exit ownership) x exit equity value | C42: =-(C13-C21)*C20 -> -80.834107 | D42: =-(D13-D21)*D20 -> -112.95816 | E42: =-(E13-E21)*E20 -> -56.2545
...

Sheet Key Stats
A5: Dynacast International Inc. > Financials > Key Stats
A7: In Millions of the trading currency, except per share items. | B7: Currency: | C7: Trading Currency | E7: Conversion: | F7: Today's Spot Rate
B8: Order: | C8: Latest on Right | E8: Units: | F8: S&P Capital IQ (Default)
B9: Decimals: | C9: Capital IQ (Default) | E9: Dilution: | F9: Basic
A12: Key Financials¹
A13: For the Fiscal Period Ending | B13: 12 months Dec-31-2008A | C13: 12 months Dec-31-2009A | D13: 12 months Dec-31-2010A | E13: 12 months Dec-31-2011A | F13: 12 months Dec-31-2012A | G13: 12 months Dec-31-2013A | H13: LTM² 12 months Sep-30-2014A | I13: 3Yr CAGR | J13: 5YR CAGR
A14: Year | B14: 0 | C14: =B14+1 -> 1 | D14: =C14+1 -> 2 | E14: =D14+1 -> 3 | F14: =E14+1 -> 4 | G14: =F14+1 -> 5 | H14: =G14+1 -> 6
A15: Currency | B15: USD | C15: USD | D15: USD | E15: USD | F15: USD | G15: USD | H15: USD
A17: Total Revenue | B17: 457.5 | C17: 327.8 | D17: 428.4 | E17: 478.7 | F17: 519.4 | G17: 580 | H17: 616.7 | I17: =((H17/E17)^(1/($H$14-E$14)))-1 -> 0.088103416 | J17: =((H17/C17)^(1/($H$14-C$14)))-1 -> 0.13473121
A18: Growth Over Prior Year | B18: NA | C18: -0.283498 | D18: 0.306894 | E18: 0.117413 | F18: 0.085021 | G18: 0.116673 | H18: 0.080602
A20: Gross Profit | B20: 95.4 | C20: 68.7 | D20: 102.2 | E20: 110.1 | F20: 121.4 | G20: 138.3 | H20: 145 | I20: =((H20/E20)^(1/($H$14-E$14)))-1 -> 0.096125365 | J20: =((H20/C20)^(1/($H$14-C$14)))-1 -> 0.16113376
A21: Margin % | B21: 0.208524 | C21: 0.209579 | D21: 0.238562 | E21: 0.229997 | F21: 0.233731 | G21: 0.238448 | H21: 0.235122
A23: EBITDA | B23: 66.4 | C23: 49.2 | D23: 78.3 | E23: 86.5 | F23: 91.7 | G23: 103.9 | H23: 113 | I23: =((H23/E23)^(1/($H$14-E$14)))-1 -> 0.093169347
A24: Margin % | B24: 0.145136 | C24: 0.150091 | D24: 0.182773 | E24: 0.180697 | F24: 0.176549 | G24: 0.179137 | H24: 0.183233
A26: EBIT | B26: 48.2 | C26: 31.1 | D26: 62.4 | E26: 64.4 | F26: 59.3 | G26: 69.4 | H26: 74.8 | I26: =((H26/E26)^(1/($H$14-E$14)))-1 -> 0.051167464 | J26: =((H26/C26)^(1/($H$14-C$14)))-1 -> 0.19186823
A27: Margin % | B27: 0.105355 | C27: 0.094874 | D27: 0.145658 | E27: 0.134531 | F27: 0.11417 | G27: 0.119655 | H27: 0.12129
A29: Earnings from Cont. Ops. | B29: 26.2 | C29: 14.5 | D29: 43.5 | E29: 7.4 | F29: -0.6 | G29: 1.2 | H29: 11 | I29: =((H29/E29)^(1/($H$14-E$14)))-1 -> 0.14126629 | J29: =((H29/C29)^(1/($H$14-C$14)))-1 -> -0.053752083
A30: Margin % | B30: 0.057267 | C30: 0.044234 | D30: 0.10154 | E30: 0.015458 | F30: -0.001155 | G30: 0.002068 | H30: 0.017836
A32: Net Income | B32: 25.8 | C32: 14.2 | D32: 43.1 | E32: 7.1 | F32: -0.9 | G32: 0.8 | H32: 10.5 | I32: =((H32/E32)^(1/($H$14-E$14)))-1 -> 0.13931457 | J32: =((H32/C32)^(1/($H$14-C$14)))-1 -> -0.058587001
A33: Margin % | B33: 0.056393 | C33: 0.043319 | D33: 0.100606 | E33: 0.014831 | F33: -0.001732 | G33: 0.001379 | H33: 0.017026
A35: Diluted EPS Excl. Extra Items³ | B35: NA | C35: NA | D35: NA | E35: -144.12 | F35: -6.47 | G35: 4.705882 | H35: 61.764705
A36: Growth Over Prior Year | B36: NA | C36: NA | D36: NA | E36: NA | F36: NM | G36: NM | H36: 2
A41: ¹All results are taken from the most recently filed statement for each period. When there has been more than one, earlier filings can be viewed on the individual statement pages.
A42: ²Growth rates for the LTM period are calculated against the LTM period ending 12 months before.
A45: Latest Capitalization (Millions of USD)
A46: Currency | B46: USD
A47: Share Price | B47: -
A48: Shares Out. | B48: -
A50: Market Capitalization | B50: -
A51: - Cash & Short Term Investments | B51: 40.3
A52: + Total Debt | B52: 486 | C52: =B52/H23 -> 4.300885
A53: + Pref. Equity | B53: -
A54: + Total Minority Interest | B54: 4.2
A55: - Long Term Marketable Securities | B55: -
A56: = Total Enterprise Value (TEV) | B56: -
A58: Book Value of Common Equity | B58: 120.7
A59: + Pref. Equity | B59: -
A60: + Total Minority Interest | B60: 4.2
A61: + Total Debt | B61: 486
A62: = Total Capital | B62: 610.9
...

Sheet Income Statement
A5: Dynacast International Inc. > Financials > Income Statement
A7: In Millions of the reported currency, except per share items. | B7: Template: | C7: Standard | E7: Restatement: | F7: Latest Filings
B8: Period Type: | C8: Annual | E8: Order: | F8: Latest on Right
B9: Currency: | C9: Reported Currency | E9: Conversion: | F9: Today's Spot Rate
B10: Units: | C10: S&P Capital IQ (Default) | E10: Decimals: | F10: Capital IQ (Default)
B11: Source: | C11: Capital IQ & Proprietary Data
A14: Income Statement
A15: For the Fiscal Period Ending | B15: 12 months Dec-31-2009 | C15: Reclassified 12 months Dec-31-2010 | D15: Restated 12 months Dec-31-2011 | E15: Reclassified 12 months Dec-31-2012 | F15: 12 months Dec-31-2013 | G15: LTM 12 months Sep-30-2014
A16: Currency | B16: USD | C16: USD | D16: USD | E16: USD | F16: USD | G16: USD
A18: Revenue | B18: 327.8 | C18: 428.4 | D18: 478.7 | E18: 519.4 | F18: 580 | G18: 616.7
A19: Other Revenue | B19: - | C19: - | D19: - | E19: - | F19: - | G19: -
A20: Total Revenue | B20: 327.8 | C20: 428.4 | D20: 478.7 | E20: 519.4 | F20: 580 | G20: 616.7
A22: Cost Of Goods Sold | B22: 259.1 | C22: 326.2 | D22: 368.6 | E22: 398 | F22: 441.7 | G22: 471.7
A23: Gross Profit | B23: 68.7 | C23: 102.2 | D23: 110.1 | E23: 121.4 | F23: 138.3 | G23: 145
A25: Selling General & Admin Exp. | B25: 37.6 | C25: 39.8 | D25: 45.7 | E25: 62.1 | F25: 68.9 | G25: 70.2
A26: R & D Exp. | B26: - | C26: - | D26: - | E26: - | F26: - | G26: -
A27: Depreciation & Amort. | B27: - | C27: - | D27: - | E27: - | F27: - | G27: -
A28: Other Operating Expense/(Income) | B28: - | C28: - | D28: - | E28: - | F28: - | G28: -
A30: Other Operating Exp., Total | B30: 37.6 | C30: 39.8 | D30: 45.7 | E30: 62.1 | F30: 68.9 | G30: 70.2
A32: Operating Income | B32: 31.1 | C32: 62.4 | D32: 64.4 | E32: 59.3 | F32: 69.4 | G32: 74.8
A34: Interest Expense | B34: -8.1 | C34: -4.9 | D34: -27.7 | E34: -48.7 | F34: -47.9 | G34: -46
A35: Interest and Invest. Income | B35: - | C35: 1.2 | D35: - | E35: - | F35: - | G35: -
A36: Net Interest Exp. | B36: -8.1 | C36: -3.7 | D36: -27.7 | E36: -48.7 | F36: -47.9 | G36: -46
A40: Currency Exchange Gains (Loss) | B40: - | C40: - | D40: - | E40: - | F40: - | G40: 1.5
A41: Other Non-Operating Inc. (Exp.) | B41: 2.5 | C41: - | D41: 0.7 | E41: -3.2 | F41: -5.7 | G41: -7.4
A42: EBT Excl. Unusual Items | B42: 25.5 | C42: 58.7 | D42: 37.4 | E42: 7.4 | F42: 15.8 | G42: 22.9
A44: Restructuring Charges | B44: -2.9 | C44: -10.9 | D44: 0.7 | E44: -0.5 | F44: - | G44: -
A45: Merger & Related Restruct. Charges | B45: - | C45: - | D45: -23 | E45: -0.6 | F45: - | G45: -1.4
A46: Impairment of Goodwill | B46: - | C46: - | D46: - | E46: - | F46: - | G46: -
A47: Insurance Settlements | B47: - | C47: - | D47: - | E47: - | F47: - | G47: 2.3
A48: Other Unusual Items | B48: - | C48: -0.7 | D48: - | E48: - | F48: - | G48: -0.4
A49: EBT Incl. Unusual Items | B49: 22.6 | C49: 47.1 | D49: 15.1 | E49: 6.3 | F49: 15.8 | G49: 23.4
A51: Income Tax Expense | B51: 8.1 | C51: 3.6 | D51: 7.7 | E51: 6.9 | F51: 14.6 | G51: 12.4
A52: Earnings from Cont. Ops. | B52: 14.5 | C52: 43.5 | D52: 7.4 | E52: -0.6 | F52: 1.2 | G52: 11
A54: Earnings of Discontinued Ops. | B54: - | C54: - | D54: - | E54: - | F54: - | G54: -
A55: Extraord. Item & Account. Change | B55: - | C55: - | D55: - | E55: - | F55: - | G55: -
A56: Net Income to Company | B56: 14.5 | C56: 43.5 | D56: 7.4 | E56: -0.6 | F56: 1.2 | G56: 11
A58: Minority Int. in Earnings | B58: -0.3 | C58: -0.4 | D58: -0.3 | E58: -0.3 | F58: -0.4 | G58: -0.5
A59: Net Income | B59: 14.2 | C59: 43.1 | D59: 7.1 | E59: -0.9 | F59: 0.8 | G59: 10.5
A61: Pref. Dividends and Other Adj. | B61: - | C61: - | D61: 31.6 | E61: 0.2 | F61: - | G61: -
...

Sheet Balance Sheet
A5: Dynacast International Inc. > Financials > Balance Sheet
A7: In Millions of the reported currency, except per share items. | B7: Template: | C7: Standard | E7: Restatement: | F7: Latest Filings
B8: Period Type: | C8: Annual | E8: Order: | F8: Latest on Right
B9: Currency: | C9: Reported Currency | E9: Conversion: | F9: Today's Spot Rate
B10: Units: | C10: S&P Capital IQ (Default) | E10: Decimals: | F10: Capital IQ (Default)
B11: Source: | C11: Capital IQ & Proprietary Data
A14: Balance Sheet
A15: Balance Sheet as of: | B15: 40178 | C15: 40543 | D15: 40908 | E15: Restated Dec-31-2012 | F15: 41639 | G15: 41912
A16: Currency | B16: USD | C16: USD | D16: USD | E16: USD | F16: USD | G16: USD
A17: ASSETS
A18: Cash And Equivalents | B18: 57.3 | C18: 27.8 | D18: 21.1 | E18: 28 | F18: 36.8 | G18: 40.3
A19: Total Cash & ST Investments | B19: 57.3 | C19: 27.8 | D19: 21.1 | E19: 28 | F19: 36.8 | G19: 40.3
I20: NWC Build | J20: FYE Dec 2013 | K20: LTM Sep 2014
A21: Accounts Receivable | B21: 51.8 | C21: 60.4 | D21: 66.9 | E21: 87.6 | F21: 97 | G21: 108 | I21: CA | J21: =F21+SUM(F25:F28) -> 162.1 | K21: =G21+SUM(G25:G28) -> 181.6
A22: Other Receivables | B22: 4.1 | C22: 0.2 | D22: - | E22: - | F22: - | G22: - | I22: CL | J22: =F50-F45 -> 155.3 | K22: =G50-G45 -> 146.4
A23: Total Receivables | B23: 55.9 | C23: 60.6 | D23: 66.9 | E23: 87.6 | F23: 97 | G23: 108 | I23: NWC | J23: =J21-J22 -> 6.8 | K23: =K21-K22 -> 35.2
I24: Net Change | K24: =J23-K23 -> -28.4
A25: Inventory | B25: 30.1 | C25: 36.2 | D25: 39 | E25: 36.7 | F25: 45 | G25: 49.7
A26: Prepaid Exp. | B26: 1.9 | C26: 2 | D26: 8.2 | E26: 14.2 | F26: 15.2 | G26: 17.4
A27: Deferred Tax Assets, Curr. | B27: 1.9 | C27: 5.5 | D27: 5.8 | E27: 4.3 | F27: 4.9 | G27: 5.9
A28: Other Current Assets | B28: 0.6 | C28: 4.3 | D28: 1.3 | E28: 0.3 | F28: - | G28: 0.6
A29: Total Current Assets | B29: 147.7 | C29: 136.4 | D29: 142.3 | E29: 171.1 | F29: 198.9 | G29: 221.9
A31: Gross Property, Plant & Equipment | B31: 233.5 | C31: 219 | D31: 126.4 | E31: 151.2 | F31: 190.4 | G31: -
A32: Accumulated Depreciation | B32: -168.3 | C32: -155.5 | D32: -6.5 | E32: -23.7 | F32: -41.7 | G32: -
A33: Net Property, Plant & Equipment | B33: 65.2 | C33: 63.5 | D33: 119.9 | E33: 127.5 | F33: 148.7 | G33: 153.3
A35: Goodwill | B35: 326.9 | C35: 320.8 | D35: 238.4 | E35: 242.8 | F35: 246.7 | G35: 264.4
A36: Other Intangibles | B36: 37.8 | C36: 32.6 | D36: 270.7 | E36: 261.9 | F36: 249 | G36: 240.8
A37: Deferred Tax Assets, LT | B37: 0.1 | C37: 2 | D37: 4.9 | E37: 5.3 | F37: 5.1 | G37: 4.3
A38: Deferred Charges, LT | B38: - | C38: - | D38: 22.1 | E38: 19.7 | F38: 15.7 | G38: 13.4
A39: Other Long-Term Assets | B39: - | C39: - | D39: 2.2 | E39: 4.5 | F39: 4.6 | G39: 4.3
A40: Total Assets | B40: 577.7 | C40: 555.3 | D40: 800.5 | E40: 832.8 | F40: 868.7 | G40: 902.4
A42: LIABILITIES
A43: Accounts Payable | B43: 47.4 | C43: 48.6 | D43: 52.7 | E43: 62.1 | F43: 67.7 | G43: 65.6
A44: Accrued Exp. | B44: 23.9 | C44: 30.5 | D44: 58.1 | E44: 64 | F44: 60.2 | G44: 57.3
A45: Curr. Port. of LT Debt | B45: 0.9 | C45: 0.4 | D45: 5 | E45: 6.3 | F45: 5.6 | G45: 19.5
A46: Curr. Income Taxes Payable | B46: 6.5 | C46: 2.7 | D46: 6.8 | E46: 3 | F46: 5.8 | G46: 6.2
A47: Unearned Revenue, Current | B47: 8.7 | C47: 8.2 | D47: 8.4 | E47: 8.4 | F47: 17.5 | G47: 16.2
A48: Def. Tax Liability, Curr. | B48: 0.9 | C48: 1.1 | D48: 1.3 | E48: 0.2 | F48: 0.4 | G48: 0.6
A49: Other Current Liabilities | B49: 4.8 | C49: 10.8 | D49: 0.2 | E49: 1.4 | F49: 3.7 | G49: 0.5
A50: Total Current Liabilities | B50: 93.1 | C50: 102.3 | D50: 132.5 | E50: 145.4 | F50: 160.9 | G50: 165.9
...

Sheet Cash Flow
A5: Dynacast International Inc. > Financials > Cash Flow
A7: In Millions of the reported currency, except per share items. | B7: Template: | C7: Standard | E7: Restatement: | F7: Latest Filings
B8: Period Type: | C8: Annual | E8: Order: | F8: Latest on Right
B9: Currency: | C9: Reported Currency | E9: Conversion: | F9: Today's Spot Rate
B10: Units: | C10: S&P Capital IQ (Default) | E10: Decimals: | F10: Capital IQ (Default)
B11: Source: | C11: Capital IQ & Proprietary Data
A14: Cash Flow
A15: For the Fiscal Period Ending | B15: 12 months Dec-31-2009 | C15: 12 months Dec-31-2010 | D15: Restated 12 months Dec-31-2011 | E15: 12 months Dec-31-2012 | F15: 12 months Dec-31-2013 | G15: LTM 12 months Sep-30-2014
A16: Currency | B16: USD | C16: USD | D16: USD | E16: USD | F16: USD | G16: USD
A18: Net Income | B18: 14.2 | C18: 43.1 | D18: 7.4 | E18: -0.9 | F18: 0.8 | G18: 10.5
A19: Depreciation & Amort. | B19: 13.7 | C19: 11.7 | D19: 12.8 | E19: 16.5 | F19: 18.7 | G19: 22.6
A20: Amort. of Goodwill and Intangibles | B20: 4.4 | C20: 4.2 | D20: 9.3 | E20: 15.9 | F20: 15.8 | G20: 15.6
A21: Depreciation & Amort., Total | B21: 18.1 | C21: 15.9 | D21: 22.1 | E21: 32.4 | F21: 34.5 | G21: 38.2
A23: Other Amortization | B23: - | C23: - | D23: 7.1 | E23: 3.8 | F23: 4.8 | G23: 4.3
A24: Other Operating Activities | B24: 2.8 | C24: 1.7 | D24: 20.6 | E24: 8.8 | F24: 14.1 | G24: 7.2
A25: Change in Acc. Receivable | B25: 9.5 | C25: -8.8 | D25: -5.9 | E25: -20 | F25: -8.7 | G25: -7.1
A26: Change In Inventories | B26: 3.2 | C26: -6 | D26: -3.4 | E26: -3.4 | F26: -8 | G26: -7.5
A27: Change in Acc. Payable | B27: -1.2 | C27: 14.6 | D27: 10 | E27: 14 | F27: 5.1 | G27: 12.2
A28: Change in Inc. Taxes | B28: -2.1 | C28: -4.1 | D28: -2.7 | E28: 0.4 | F28: 4.7 | G28: 6.5
A29: Change in Other Net Operating Assets | B29: 3.2 | C29: 5.2 | D29: 0.1 | E29: -2.7 | F29: 6 | G29: -6.2
A30: Cash from Ops. | B30: 47.7 | C30: 61.6 | D30: 55.3 | E30: 32.4 | F30: 53.3 | G30: 58.1
A32: Capital Expenditure | B32: -6.9 | C32: -9.5 | D32: -14.3 | E32: -22 | F32: -39.7 | G32: -35.8
A33: Cash Acquisitions | B33: - | C33: - | D33: -586.4 | E33: - | F33: - | G33: -45.1
A34: Divestitures | B34: - | C34: - | D34: - | E34: - | F34: - | G34: -
A35: Invest. in Marketable & Equity Securt. | B35: - | C35: - | D35: - | E35: - | F35: - | G35: -
A36: Net (Inc.) Dec. in Loans Originated/Sold | B36: - | C36: - | D36: - | E36: - | F36: - | G36: -
A37: Other Investing Activities | B37: -27.2 | C37: -14.6 | D37: 27 | E37: 1.6 | F37: 0.1 | G37: -0.4
A38: Cash from Investing | B38: -34.1 | C38: -24.1 | D38: -573.7 | E38: -20.4 | F38: -39.6 | G38: -81.3
A40: Short Term Debt Issued | B40: - | C40: - | D40: 6.5 | E40: 24.5 | F40: 13.9 | G40: -
A41: Long-Term Debt Issued | B41: - | C41: - | D41: 400 | E41: - | F41: 5.8 | G41: -
A42: Total Debt Issued | B42: - | C42: - | D42: 406.5 | E42: 24.5 | F42: 19.7 | G42: 52.3
A43: Short Term Debt Repaid | B43: - | C43: - | D43: -34.1 | E43: -24.5 | F43: -13.9 | G43: -
A44: Long-Term Debt Repaid | B44: -1.3 | C44: -0.9 | D44: -2.9 | E44: -5 | F44: -8.1 | G44: -
A45: Total Debt Repaid | B45: -1.3 | C45: -0.9 | D45: -37 | E45: -29.5 | F45: -22 | G45: -9.2
A47: Issuance of Common Stock | B47: - | C47: - | D47: 174.3 | E47: - | F47: - | G47: -
A48: Issuance of Pref. Stock | B48: - | C48: - | D48: 53 | E48: - | F48: - | G48: -
A50: Pref. Dividends Paid | B50: - | C50: - | D50: - | E50: - | F50: -1.8 | G50: -7.1
A51: Common and/or Pref. Dividends Paid | B51: - | C51: -11 | D51: -12.9 | E51: - | F51: - | G51: -
A52: Total Dividends Paid | B52: - | C52: -11 | D52: -12.9 | E52: - | F52: -1.8 | G52: -7.1
A54: Special Dividend Paid | B54: - | C54: - | D54: - | E54: - | F54: - | G54: -
...

Sheet Capital Structure Summary
A5: Dynacast International Inc. > Financials > Capital Structure Summary
A7: In Millions of the reported currency, except ratios and % of Total values. | B7: Restatement: | C7: Latest Filings | E7: Period Type: | F7: Annual
B8: Currency: | C8: Reported Currency | E8: Conversion: | F8: Today's Spot Rate
B9: Units: | C9: S&P Capital IQ (Default) | E9: Decimals: | F9: Capital IQ (Default)
B10: Order: | C10: Latest on Right
A13: Capital Structure Data
A14: For the Fiscal Period Ending | B14: 12 months Dec-31-2012 | D14: 12 months Dec-31-2013 | F14: 3 months Sep-30-2014
A15: Currency | B15: USD | D15: USD | F15: USD
A16: Units | B16: Millions | C16: % of Total | D16: Millions | E16: % of Total | F16: Millions | G16: % of Total
A18: Total Debt | B18: 445.5 | C18: 0.77789419 | D18: 443.3 | E18: 0.76788498 | F18: 486 | G18: 0.79554755
A19: Total Common Equity | B19: 123.4 | C19: 0.21547058 | D19: 129.9 | E19: 0.22501299 | F19: 120.7 | G19: 0.19757734
A20: Total Minority Interest | B20: 3.8 | C20: 0.0066352366 | D20: 4.1 | E20: 0.0071020267 | F20: 4.2 | G20: 0.0068751023
A21: Total Capital | B21: 572.7 | C21: 1 | D21: 577.3 | E21: 1 | F21: 610.9 | G21: 1
A24: Currency | B24: USD | D24: USD | F24: USD
A25: Exchange Rate | B25: 1 | D25: 1 | F25: 1
A26: Conversion Method | B26: S | D26: S | F26: S
A29: Debt Summary Data
A30: For the Fiscal Period Ending | B30: 12 months Dec-31-2012 | D30: 12 months Dec-31-2013 | F30: 3 months Sep-30-2014
A31: Currency | B31: USD | D31: USD | F31: USD
A32: Units | B32: Millions | C32: % of Total | D32: Millions | E32: % of Total | F32: Millions | G32: % of Total
A34: Total Revolving Credit | B34: - | C34: - | D34: 0 | E34: 0 | F34: 0 | G34: 0
A35: Total Term Loans | B35: 42.5 | C35: 0.095398 | D35: 40.3 | E35: 0.090909 | F35: 83 | G35: 0.170781
A36: Total Senior Bonds and Notes | B36: 350 | C36: 0.785634 | D36: 350 | E36: 0.789533 | F36: 350 | G36: 0.720164
A37: General/Other Borrowings | B37: 53 | C37: 0.118967 | D37: 53 | E37: 0.119557 | F37: 53 | G37: 0.109053
A38: Total Principal Due | B38: 445.5 | C38: 1 | D38: 443.3 | E38: 1 | F38: 486 | G38: 1
A40: Total Debt Outstanding | B40: 445.5 | C40: 1 | D40: 443.3 | E40: 1 | F40: 486 | G40: 1
A42: Available Credit
A43: Undrawn Revolving Credit | B43: - | C43: - | D43: 48.7 | E43: - | F43: 51.6 | G43: -
A44: Total Undrawn Credit | B44: - | C44: - | D44: 48.7 | E44: - | F44: 51.6 | G44: -
A46: Additional Totals
A47: Total Cash & ST Investments | B47: 28 | C47: - | D47: 36.8 | E47: - | F47: 40.3 | G47: -
A48: Net Debt | B48: 417.5 | C48: - | D48: 406.5 | E48: - | F48: 445.7 | G48: -
A49: Total Senior Debt | B49: 445.5 | C49: 1 | D49: 443.3 | E49: 1 | F49: 486 | G49: 1
A50: Total Convertible Debt | B50: 403 | C50: 0.904601 | D50: 403 | E50: 0.90909 | F50: 403 | G50: 0.829218
A51: Curr. Port. of LT Debt/Cap. Leases | B51: 6.3 | C51: 0.014141 | D51: 5.6 | E51: 0.012632 | F51: 19.5 | G51: 0.040123
A52: Long-Term Debt (Incl. Cap. Leases) | B52: 439.2 | C52: 0.985858 | D52: 437.7 | E52: 0.987367 | F52: 466.5 | G52: 0.959876
A53: Total Bank Debt | B53: 42.5 | C53: 0.095398 | D53: 40.3 | E53: 0.090909 | F53: 83 | G53: 0.170781
A54: Total Secured Debt | B54: 392.5 | C54: 0.881032 | D54: 384.4 | E54: 0.867132 | F54: 427.5 | G54: 0.879629
A55: Senior Secured Loans | B55: 42.5 | C55: 0.095398 | D55: 34.4 | E55: 0.077599 | F55: 77.5 | G55: 0.159465
A56: Senior Secured Bonds and Notes | B56: 350 | C56: 0.785634 | D56: 350 | E56: 0.789533 | F56: 350 | G56: 0.720164
...

Sheet Quick IRR rule of thumb
B3: Quick Approx IRRs
B4: MOIC | C4: TIME | D4: IRR
B5: 2 | C5: 1 | D5: 1
B6: 2 | C6: 2 | D6: 0.4
B7: 2 | C7: 3 | D7: 0.25
B8: 2 | C8: 4 | D8: 0.2
B9: 2 | C9: 5 | D9: 0.15
B11: Quick Approx IRRs
B12: MOIC | C12: TIME | D12: IRR
B13: 3 | C13: 3 | D13: 0.45
B14: 3 | C14: 5 | D14: 0.25
B16: Quick Approx IRRs
B17: MOIC | C17: TIME | D17: IRR
B18: 2 | C18: 3 | D18: 0.25
B19: 2.5 | C19: 3 | D19: 0.35
B20: 3 | C20: 3 | D20: 0.45
B22: Quick Approx IRRs
B23: MOIC | C23: TIME | D23: IRR
B24: 2 | C24: 5 | D24: 0.15
B25: 2.5 | C25: 5 | D25: 0.2
B26: 3 | C26: 5 | D26: 0.25
